Workbook

Sheet Read Me
A1: The Chill Bottle Shop — Financial Model
A2: Placeholder model for planning, lending and investor conversations. Every number in blue is an assumption to replace with real quotes.
A4: How to use
A5: 1. Edit only blue cells on the Assumptions and Startup Costs sheets. Yellow cells are the key drivers.
A6: 2. Everything else is a formula: Monthly P&L, Annual Summary, Break-even and Budget Export update automatically.
A7: 3. Budget Export is in the exact month,line,amount format the admin finance dashboard imports. Copy columns A:C (with the header) and paste into Admin → Finance → Budget import.
A9: Colour key
A10: Blue text = hardcoded input · Black = formula · Green = link to another sheet · Yellow fill = key assumption
A12: Accounting conventions
A13: • Cash basis for membership fees: an annual fee is booked in the month it is charged (join or renewal), matching the dashboard's actuals.
A14: • Beer revenue excludes Hawaiʻi GET, which is added at checkout and remitted.
A15: • Refunds are forfeited-order refunds (90% of the order); resale of forfeited beer to the waitlist is not modeled (conservative).
... A23: • Rent, build-out, equipment, payroll, insurance and legal costs: rough Oʻahu estimates, NOT quotes. Replace before sharing with a lender.

Sheet Assumptions
A1: Assumptions
A2: Blue = input. Yellow = key driver. Year columns apply to operating years 1–3 counted from launch.
A4: Assumption | B4: Unit | C4: Year 1 | D4: Year 2 | E4: Year 3 | F4: Note / source
A5: Timing
A6: First month of sales (after Class 4 license) | B6: date | C6: 46478 | F6: Placeholder: ~6 months for legal opinion, lease, application, notice and hearing.
A7: Local delivery starts in operating month | B7: month # | C7: 7 | F7: Phase 2 per product spec.
A8: Membership
A9: Founding annual fee | B9: $/yr | C9: 150 | F9: Placeholder; research: access clubs $99–$325/yr.
A10: Member annual fee | B10: $/yr | C10: 75 | F10: Placeholder.
A11: Founding cap | B11: members | C11: 100 | F11: Per spec.
A12: Founding members at launch | B12: members | C12: 60 | F12: Offered to the waitlist first.
A13: Founding adds per month until cap | B13: members/mo | C13: 8
A14: Members at launch | B14: members | C14: 150 | F14: Waitlist conversion; placeholder.
A15: Member gross adds per month | B15: members/mo | C15: 50 | D15: 35 | E15: 25 | F15: Placeholder ramp.
A16: Member churn | B16: %/month | C16: 0.02 | F16: ≈22%/yr; wine clubs lose 20–36%/yr (research).
A17: Founding churn | B17: %/month | C17: 0 | F17: Spots refilled from the waitlist.
A18: Beer sales
A19: Members buying in a given month | B19: % | C19: 0.65 | D19: 0.7 | E19: 0.72 | F19: Placeholder.
A20: Average beer spend per buying member | B20: $/month | C20: 65 | D20: 68 | E20: 70 | F20: About three specialty 4-packs a month. Research: would-be direct buyers cite ~$104/mo.
A21: Beer cost (Von Oster invoice) as % of beer sales | B21: % | C21: 0.68 | F21: Targets ~32% gross margin on specialty beer; confirm with Von Oster price list.
A22: Orders forfeited (not collected) | B22: % of sales | C22: 0.02
A23: Refund on forfeited orders | B23: % | C23: 0.9 | F23: Per allocation_policy.
A24: Variable costs
A25: Card processing | B25: % of revenue | C25: 0.032 | F25: Stripe ~2.9% + $0.30; blended estimate.
A26: Supplies and packaging | B26: % of beer sales | C26: 0.015
A27: Average order value | B27: $ | C27: 50 | F27: Used for delivery count.
A28: Orders delivered (after delivery starts) | B28: % | C28: 0.25
A29: Net cost per delivery after delivery fee | B29: $ | C29: 3 | F29: Assumes a delivery fee covers most of the cost.
A30: SMS, email and ID checks per active member | B30: $/month | C30: 0.15 | F30: Twilio/Resend/AgeChecker usage.
A31: Fixed monthly costs
A32: Rent incl. CAM (~1,200 sq ft) | B32: $/month | C32: 3600 | F32: Placeholder: ~$3/sq ft/mo Kakaʻako/Kalihi/Iwilei. Get quotes.
A33: Rent escalator | B33: %/yr | C33: 0.03
A34: Utilities incl. walk-in cooler power | B34: $/month | C34: 900 | F34: Hawaiʻi electricity is expensive; placeholder.
A35: Shop manager / registered liquor manager | B35: $/yr | C35: 55000 | F35: Placeholder.
A36: Part-time counter staff | B36: people | C36: 1 | D36: 2 | E36: 2 | F36: Manager covers most pickup windows in year 1.
A37: Hours per part-timer | B37: hrs/week | C37: 20
A38: Part-time wage | B38: $/hr | C38: 20
A39: Payroll taxes and benefits | B39: % of wages | C39: 0.12
A40: Insurance (GL, liquor liability, property, WC) | B40: $/month | C40: 650 | F40: Get broker quote.
A41: Licenses and permits (annual fees, amortized) | B41: $/month | C41: 150 | F41: Confirm Class 4 fee with Honolulu Liquor Commission.
...

Sheet Startup Costs
A1: Startup costs and funding ($)
A2: Blue = input (placeholder estimates, not quotes). 'Capital' items are depreciated.
A4: Item | B4: Capital? | C4: Amount ($) | D4: Note
A5: Legal: HRS §281-42 opinion, entity, license application | B5: N | C5: 12000 | D5: Liquor attorney; placeholder.
A6: License and permit fees (application, first year) | B6: N | C6: 2500 | D6: Confirm with Honolulu Liquor Commission.
A7: Lease deposit (2 months) | B7: N | C7: =2*Assumptions!$C$32 -> 7200 | D7: Formula from rent.
A8: Rent during build-out and licensing (3 months) | B8: N | C8: =3*Assumptions!$C$32 -> 10800 | D8: Formula from rent.
A9: Build-out: electrical, counter, finishes | B9: Y | C9: 20000 | D9: Placeholder.
A10: Walk-in cooler, installed | B10: Y | C10: 18000 | D10: Placeholder; get quotes.
A11: Shelving, racking and fixtures | B11: Y | C11: 6000
A12: POS hardware, ID scanners and tablets | B12: Y | C12: 3000
A13: Signage and branding | B13: N | C13: 3000
A14: Insurance deposit | B14: N | C14: 2000
A15: Opening supplies and packaging | B15: N | C15: 1500
A16: Pre-launch marketing | B16: N | C16: 5000 | D16: Waitlist and Founding launch.
A17: Contingency (10% of the above) | C17: =0.1*SUM(C5:C16) -> 9100
A18: Projected operating losses to fund (deepest cumulative cash shortfall) | C18: =MAX(0,-MIN('Monthly P&L'!$C$48:$AL$48)) -> 93229.087
A19: Cash cushion (months of month-1 fixed costs) | C19: =Assumptions!$C$51*('Monthly P&L'!$C$25+'Monthly P&L'!$C$26+'Monthly P&L'!$C$27+'Monthly P&L'!$C$28+'Monthly P&L'!$C$29+'Monthly P&L'!$C$32+'Monthly P&L'!$C$33+'Monthly P&L'!$C$36+Assumptions!$C$42) -> 30749.333
A20: Total funding needed | C20: =SUM(C5:C19) -> 224078.42
A22: Capital items (depreciated) | C22: =SUMIF(B5:B16,"Y",C5:C16) -> 47000
A24: Funding sources
A25: SBA 7(a) loan | C25: =Assumptions!$C$48 -> 100000
A26: Owner equity required | C26: =MAX(0,C20-C25) -> 124078.42
A27: Total sources | C27: =C25+C26 -> 224078.42
A29: Opening cash at launch (sources − spend before launch) | C29: =C27-SUM(C5:C17) -> 123978.42

Sheet Monthly P&L
A1: Monthly P&L — 36 months from launch ($)
A2: All formulas. Edit inputs on Assumptions and Startup Costs.
A4: Operating month | C4: =1 -> 1 | D4: =2 -> 2 | E4: =3 -> 3 | F4: =4 -> 4 | G4: =5 -> 5 | H4: =6 -> 6 | I4: =7 -> 7 | J4: =8 -> 8 | K4: =9 -> 9 | L4: =10 -> 10 | M4: =11 -> 11 | N4: =12 -> 12 | O4: =13 -> 13 | P4: =14 -> 14 | Q4: =15 -> 15 | R4: =16 -> 16 | S4: =17 -> 17 | T4: =18 -> 18 | U4: =19 -> 19 | V4: =20 -> 20 | W4: =21 -> 21 | X4: =22 -> 22 | Y4: =23 -> 23 | Z4: =24 -> 24 | AA4: =25 -> 25 | AB4: =26 -> 26 | AC4: =27 -> 27 | AD4: =28 -> 28 | AE4: =29 -> 29 | AF4: =30 -> 30 | AG4: =31 -> 31 | AH4: =32 -> 32 | AI4: =33 -> 33 | AJ4: =34 -> 34 | AK4: =35 -> 35 | AL4: =36 -> 36
A5: Month | C5: =EDATE(Assumptions!$C$6,C4-1) -> 46478 | D5: =EDATE(Assumptions!$C$6,D4-1) -> 46508 | E5: =EDATE(Assumptions!$C$6,E4-1) -> 46539 | F5: =EDATE(Assumptions!$C$6,F4-1) -> 46569 | G5: =EDATE(Assumptions!$C$6,G4-1) -> 46600 | H5: =EDATE(Assumptions!$C$6,H4-1) -> 46631 | I5: =EDATE(Assumptions!$C$6,I4-1) -> 46661 | J5: =EDATE(Assumptions!$C$6,J4-1) -> 46692 | ... AL5: =EDATE(Assumptions!$C$6,AL4-1) -> 47543
A6: Operating year | C6: =INT((C4-1)/12)+1 -> 1 | D6: =INT((D4-1)/12)+1 -> 1 | E6: =INT((E4-1)/12)+1 -> 1 | F6: =INT((F4-1)/12)+1 -> 1 | G6: =INT((G4-1)/12)+1 -> 1 | H6: =INT((H4-1)/12)+1 -> 1 | I6: =INT((I4-1)/12)+1 -> 1 | J6: =INT((J4-1)/12)+1 -> 1 | ... AL6: =INT((AL4-1)/12)+1 -> 3
A7: Members
A8: Founding gross adds | C8: =Assumptions!$C$12 -> 60 | D8: =MIN(Assumptions!$C$13,MAX(0,Assumptions!$C$11-C9*(1-Assumptions!$C$17))) -> 8 | E8: =MIN(Assumptions!$C$13,MAX(0,Assumptions!$C$11-D9*(1-Assumptions!$C$17))) -> 8 | F8: =MIN(Assumptions!$C$13,MAX(0,Assumptions!$C$11-E9*(1-Assumptions!$C$17))) -> 8 | G8: =MIN(Assumptions!$C$13,MAX(0,Assumptions!$C$11-F9*(1-Assumptions!$C$17))) -> 8 | H8: =MIN(Assumptions!$C$13,MAX(0,Assumptions!$C$11-G9*(1-Assumptions!$C$17))) -> 8 | I8: =MIN(Assumptions!$C$13,MAX(0,Assumptions!$C$11-H9*(1-Assumptions!$C$17))) -> 0 | J8: =MIN(Assumptions!$C$13,MAX(0,Assumptions!$C$11-I9*(1-Assumptions!$C$17))) -> 0 | K8: =MIN(Assumptions!$C$13,MAX(0,Assumptions!$C$11-J9*(1-Assumptions!$C$17))) -> 0 | ... AL8: =MIN(Assumptions!$C$13,MAX(0,Assumptions!$C$11-AK9*(1-Assumptions!$C$17))) -> 0
A9: Founding members (end of month) | C9: =0*(1-Assumptions!$C$17)+C8 -> 60 | D9: =C9*(1-Assumptions!$C$17)+D8 -> 68 | E9: =D9*(1-Assumptions!$C$17)+E8 -> 76 | F9: =E9*(1-Assumptions!$C$17)+F8 -> 84 | G9: =F9*(1-Assumptions!$C$17)+G8 -> 92 | H9: =G9*(1-Assumptions!$C$17)+H8 -> 100 | I9: =H9*(1-Assumptions!$C$17)+I8 -> 100 | J9: =I9*(1-Assumptions!$C$17)+J8 -> 100 | K9: =J9*(1-Assumptions!$C$17)+K8 -> 100 | ... AL9: =AK9*(1-Assumptions!$C$17)+AL8 -> 100
A10: Member gross adds | C10: =Assumptions!$C$14 -> 150 | D10: =INDEX(Assumptions!$C$15:$E$15,D6) -> 50 | E10: =INDEX(Assumptions!$C$15:$E$15,E6) -> 50 | F10: =INDEX(Assumptions!$C$15:$E$15,F6) -> 50 | G10: =INDEX(Assumptions!$C$15:$E$15,G6) -> 50 | H10: =INDEX(Assumptions!$C$15:$E$15,H6) -> 50 | I10: =INDEX(Assumptions!$C$15:$E$15,I6) -> 50 | J10: =INDEX(Assumptions!$C$15:$E$15,J6) -> 50 | K10: =INDEX(Assumptions!$C$15:$E$15,K6) -> 50 | ... AL10: =INDEX(Assumptions!$C$15:$E$15,AL6) -> 25
A11: Members (end of month) | C11: =0*(1-Assumptions!$C$16)+C10 -> 150 | D11: =C11*(1-Assumptions!$C$16)+D10 -> 197 | E11: =D11*(1-Assumptions!$C$16)+E10 -> 243.06 | F11: =E11*(1-Assumptions!$C$16)+F10 -> 288.1988 | G11: =F11*(1-Assumptions!$C$16)+G10 -> 332.43482 | H11: =G11*(1-Assumptions!$C$16)+H10 -> 375.78613 | I11: =H11*(1-Assumptions!$C$16)+I10 -> 418.2704 | J11: =I11*(1-Assumptions!$C$16)+J10 -> 459.905 | K11: =J11*(1-Assumptions!$C$16)+K10 -> 500.7069 | ... AL11: =AK11*(1-Assumptions!$C$16)+AL10 -> 945.46826
A12: Total active members | C12: =C9+C11 -> 210 | D12: =D9+D11 -> 265 | E12: =E9+E11 -> 319.06 | F12: =F9+F11 -> 372.1988 | G12: =G9+G11 -> 424.43482 | H12: =H9+H11 -> 475.78613 | I12: =I9+I11 -> 518.2704 | J12: =J9+J11 -> 559.905 | ... AL12: =AL9+AL11 -> 1045.4683
A13: Founding renewals charged | C13: =0 -> 0 | D13: =0 -> 0 | E13: =0 -> 0 | F13: =0 -> 0 | G13: =0 -> 0 | H13: =0 -> 0 | I13: =0 -> 0 | J13: =0 -> 0 | ... N13: =0 -> 0 | O13: =(C8+C13)*(1-Assumptions!$C$17)^12 -> 60 | P13: =(D8+D13)*(1-Assumptions!$C$17)^12 -> 8 | Q13: =(E8+E13)*(1-Assumptions!$C$17)^12 -> 8 | R13: =(F8+F13)*(1-Assumptions!$C$17)^12 -> 8 | S13: =(G8+G13)*(1-Assumptions!$C$17)^12 -> 8 | T13: =(H8+H13)*(1-Assumptions!$C$17)^12 -> 8 | U13: =(I8+I13)*(1-Assumptions!$C$17)^12 -> 0 | V13: =(J8+J13)*(1-Assumptions!$C$17)^12 -> 0 | ... AL13: =(Z8+Z13)*(1-Assumptions!$C$17)^12 -> 0
A14: Member renewals charged | C14: =0 -> 0 | D14: =0 -> 0 | E14: =0 -> 0 | F14: =0 -> 0 | G14: =0 -> 0 | H14: =0 -> 0 | I14: =0 -> 0 | J14: =0 -> 0 | ... N14: =0 -> 0 | O14: =(C10+C14)*(1-Assumptions!$C$16)^12 -> 117.70751 | P14: =(D10+D14)*(1-Assumptions!$C$16)^12 -> 39.235836 | Q14: =(E10+E14)*(1-Assumptions!$C$16)^12 -> 39.235836 | R14: =(F10+F14)*(1-Assumptions!$C$16)^12 -> 39.235836 | S14: =(G10+G14)*(1-Assumptions!$C$16)^12 -> 39.235836 | T14: =(H10+H14)*(1-Assumptions!$C$16)^12 -> 39.235836 | U14: =(I10+I14)*(1-Assumptions!$C$16)^12 -> 39.235836 | V14: =(J10+J14)*(1-Assumptions!$C$16)^12 -> 39.235836 | ... AL14: =(Z10+Z14)*(1-Assumptions!$C$16)^12 -> 58.254102
A15: Revenue
A16: Beer sales (excl. GET) | C16: =C12*INDEX(Assumptions!$C$19:$E$19,C6)*INDEX(Assumptions!$C$20:$E$20,C6) -> 8872.5 | D16: =D12*INDEX(Assumptions!$C$19:$E$19,D6)*INDEX(Assumptions!$C$20:$E$20,D6) -> 11196.25 | E16: =E12*INDEX(Assumptions!$C$19:$E$19,E6)*INDEX(Assumptions!$C$20:$E$20,E6) -> 13480.285 | F16: =F12*INDEX(Assumptions!$C$19:$E$19,F6)*INDEX(Assumptions!$C$20:$E$20,F6) -> 15725.399 | G16: =G12*INDEX(Assumptions!$C$19:$E$19,G6)*INDEX(Assumptions!$C$20:$E$20,G6) -> 17932.371 | H16: =H12*INDEX(Assumptions!$C$19:$E$19,H6)*INDEX(Assumptions!$C$20:$E$20,H6) -> 20101.964 | I16: =I12*INDEX(Assumptions!$C$19:$E$19,I6)*INDEX(Assumptions!$C$20:$E$20,I6) -> 21896.925 | J16: =J12*INDEX(Assumptions!$C$19:$E$19,J6)*INDEX(Assumptions!$C$20:$E$20,J6) -> 23655.986 | ... AL16: =AL12*INDEX(Assumptions!$C$19:$E$19,AL6)*INDEX(Assumptions!$C$20:$E$20,AL6) -> 52691.6
A17: Refunds on forfeited orders | C17: =-C16*Assumptions!$C$22*Assumptions!$C$23 -> -159.705 | D17: =-D16*Assumptions!$C$22*Assumptions!$C$23 -> -201.5325 | E17: =-E16*Assumptions!$C$22*Assumptions!$C$23 -> -242.64513 | F17: =-F16*Assumptions!$C$22*Assumptions!$C$23 -> -283.05719 | G17: =-G16*Assumptions!$C$22*Assumptions!$C$23 -> -322.78268 | H17: =-H16*Assumptions!$C$22*Assumptions!$C$23 -> -361.83535 | I17: =-I16*Assumptions!$C$22*Assumptions!$C$23 -> -394.14464 | J17: =-J16*Assumptions!$C$22*Assumptions!$C$23 -> -425.80775 | ... AL17: =-AL16*Assumptions!$C$22*Assumptions!$C$23 -> -948.4488
A18: Membership fees (cash basis) | C18: =(C8+C13)*Assumptions!$C$9+(C10+C14)*Assumptions!$C$10 -> 20250 | D18: =(D8+D13)*Assumptions!$C$9+(D10+D14)*Assumptions!$C$10 -> 4950 | E18: =(E8+E13)*Assumptions!$C$9+(E10+E14)*Assumptions!$C$10 -> 4950 | F18: =(F8+F13)*Assumptions!$C$9+(F10+F14)*Assumptions!$C$10 -> 4950 | G18: =(G8+G13)*Assumptions!$C$9+(G10+G14)*Assumptions!$C$10 -> 4950 | H18: =(H8+H13)*Assumptions!$C$9+(H10+H14)*Assumptions!$C$10 -> 4950 | I18: =(I8+I13)*Assumptions!$C$9+(I10+I14)*Assumptions!$C$10 -> 3750 | J18: =(J8+J13)*Assumptions!$C$9+(J10+J14)*Assumptions!$C$10 -> 3750 | ... AL18: =(AL8+AL13)*Assumptions!$C$9+(AL10+AL14)*Assumptions!$C$10 -> 6244.0577
A19: Total revenue | C19: =SUM(C16:C18) -> 28962.795 | D19: =SUM(D16:D18) -> 15944.718 | E19: =SUM(E16:E18) -> 18187.64 | F19: =SUM(F16:F18) -> 20392.342 | G19: =SUM(G16:G18) -> 22559.589 | H19: =SUM(H16:H18) -> 24690.129 | I19: =SUM(I16:I18) -> 25252.78 | J19: =SUM(J16:J18) -> 26980.178 | ... AL19: =SUM(AL16:AL18) -> 57987.209
A20: Cost of goods sold
A21: Beer COGS (Von Oster invoices) | C21: =C16*Assumptions!$C$21 -> 6033.3 | D21: =D16*Assumptions!$C$21 -> 7613.45 | E21: =E16*Assumptions!$C$21 -> 9166.5938 | F21: =F16*Assumptions!$C$21 -> 10693.272 | G21: =G16*Assumptions!$C$21 -> 12194.012 | H21: =H16*Assumptions!$C$21 -> 13669.335 | I21: =I16*Assumptions!$C$21 -> 14889.909 | J21: =J16*Assumptions!$C$21 -> 16086.071 | ... AL21: =AL16*Assumptions!$C$21 -> 35830.288
A22: Gross profit | C22: =C19-C21 -> 22929.495 | D22: =D19-D21 -> 8331.2675 | E22: =E19-E21 -> 9021.0461 | F22: =F19-F21 -> 9699.0706 | G22: =G19-G21 -> 10365.576 | H22: =H19-H21 -> 11020.793 | I22: =I19-I21 -> 10362.871 | J22: =J19-J21 -> 10894.108 | ... AL22: =AL19-AL21 -> 22156.921
A23: Gross margin | C23: =IF(C19=0,0,C22/C19) -> 0.79168792 | D23: =IF(D19=0,0,D22/D19) -> 0.52250957 | E23: =IF(E19=0,0,E22/E19) -> 0.49599872 | F23: =IF(F19=0,0,F22/F19) -> 0.47562318 | G23: =IF(G19=0,0,G22/G19) -> 0.45947541 | H23: =IF(H19=0,0,H22/H19) -> 0.44636435 | I23: =IF(I19=0,0,I22/I19) -> 0.41036556 | J23: =IF(J19=0,0,J22/J19) -> 0.4037819 | ... AL23: =IF(AL19=0,0,AL22/AL19) -> 0.38210014
A24: Operating expenses
A25: Rent | C25: =Assumptions!$C$32*(1+Assumptions!$C$33)^(C6-1) -> 3600 | D25: =Assumptions!$C$32*(1+Assumptions!$C$33)^(D6-1) -> 3600 | E25: =Assumptions!$C$32*(1+Assumptions!$C$33)^(E6-1) -> 3600 | F25: =Assumptions!$C$32*(1+Assumptions!$C$33)^(F6-1) -> 3600 | G25: =Assumptions!$C$32*(1+Assumptions!$C$33)^(G6-1) -> 3600 | H25: =Assumptions!$C$32*(1+Assumptions!$C$33)^(H6-1) -> 3600 | I25: =Assumptions!$C$32*(1+Assumptions!$C$33)^(I6-1) -> 3600 | J25: =Assumptions!$C$32*(1+Assumptions!$C$33)^(J6-1) -> 3600 | ... AL25: =Assumptions!$C$32*(1+Assumptions!$C$33)^(AL6-1) -> 3819.24
A26: Utilities | C26: =Assumptions!$C$34 -> 900 | D26: =Assumptions!$C$34 -> 900 | E26: =Assumptions!$C$34 -> 900 | F26: =Assumptions!$C$34 -> 900 | G26: =Assumptions!$C$34 -> 900 | H26: =Assumptions!$C$34 -> 900 | I26: =Assumptions!$C$34 -> 900 | J26: =Assumptions!$C$34 -> 900 | ... AL26: =Assumptions!$C$34 -> 900
A27: Payroll incl. taxes | C27: =(Assumptions!$C$35/12+INDEX(Assumptions!$C$36:$E$36,C6)*Assumptions!$C$37*52/12*Assumptions!$C$38)*(1+Assumptions!$C$39) -> 7074.6667 | D27: =(Assumptions!$C$35/12+INDEX(Assumptions!$C$36:$E$36,D6)*Assumptions!$C$37*52/12*Assumptions!$C$38)*(1+Assumptions!$C$39) -> 7074.6667 | E27: =(Assumptions!$C$35/12+INDEX(Assumptions!$C$36:$E$36,E6)*Assumptions!$C$37*52/12*Assumptions!$C$38)*(1+Assumptions!$C$39) -> 7074.6667 | F27: =(Assumptions!$C$35/12+INDEX(Assumptions!$C$36:$E$36,F6)*Assumptions!$C$37*52/12*Assumptions!$C$38)*(1+Assumptions!$C$39) -> 7074.6667 | G27: =(Assumptions!$C$35/12+INDEX(Assumptions!$C$36:$E$36,G6)*Assumptions!$C$37*52/12*Assumptions!$C$38)*(1+Assumptions!$C$39) -> 7074.6667 | H27: =(Assumptions!$C$35/12+INDEX(Assumptions!$C$36:$E$36,H6)*Assumptions!$C$37*52/12*Assumptions!$C$38)*(1+Assumptions!$C$39) -> 7074.6667 | I27: =(Assumptions!$C$35/12+INDEX(Assumptions!$C$36:$E$36,I6)*Assumptions!$C$37*52/12*Assumptions!$C$38)*(1+Assumptions!$C$39) -> 7074.6667 | J27: =(Assumptions!$C$35/12+INDEX(Assumptions!$C$36:$E$36,J6)*Assumptions!$C$37*52/12*Assumptions!$C$38)*(1+Assumptions!$C$39) -> 7074.6667 | ... AL27: =(Assumptions!$C$35/12+INDEX(Assumptions!$C$36:$E$36,AL6)*Assumptions!$C$37*52/12*Assumptions!$C$38)*(1+Assumptions!$C$39) -> 9016
A28: Insurance | C28: =Assumptions!$C$40 -> 650 | D28: =Assumptions!$C$40 -> 650 | E28: =Assumptions!$C$40 -> 650 | F28: =Assumptions!$C$40 -> 650 | G28: =Assumptions!$C$40 -> 650 | H28: =Assumptions!$C$40 -> 650 | I28: =Assumptions!$C$40 -> 650 | J28: =Assumptions!$C$40 -> 650 | ... AL28: =Assumptions!$C$40 -> 650
A29: Licenses and permits | C29: =Assumptions!$C$41 -> 150 | D29: =Assumptions!$C$41 -> 150 | E29: =Assumptions!$C$41 -> 150 | F29: =Assumptions!$C$41 -> 150 | G29: =Assumptions!$C$41 -> 150 | H29: =Assumptions!$C$41 -> 150 | I29: =Assumptions!$C$41 -> 150 | J29: =Assumptions!$C$41 -> 150 | ... AL29: =Assumptions!$C$41 -> 150
A30: Software and messaging | C30: =Assumptions!$C$42+C12*Assumptions!$C$30 -> 231.5 | D30: =Assumptions!$C$42+D12*Assumptions!$C$30 -> 239.75 | E30: =Assumptions!$C$42+E12*Assumptions!$C$30 -> 247.859 | F30: =Assumptions!$C$42+F12*Assumptions!$C$30 -> 255.82982 | G30: =Assumptions!$C$42+G12*Assumptions!$C$30 -> 263.66522 | H30: =Assumptions!$C$42+H12*Assumptions!$C$30 -> 271.36792 | I30: =Assumptions!$C$42+I12*Assumptions!$C$30 -> 277.74056 | J30: =Assumptions!$C$42+J12*Assumptions!$C$30 -> 283.98575 | ... AL30: =Assumptions!$C$42+AL12*Assumptions!$C$30 -> 356.82024
A31: Card processing | C31: =(C16+C18)*Assumptions!$C$25 -> 931.92 | D31: =(D16+D18)*Assumptions!$C$25 -> 516.68 | E31: =(E16+E18)*Assumptions!$C$25 -> 589.76912 | F31: =(F16+F18)*Assumptions!$C$25 -> 661.61278 | G31: =(G16+G18)*Assumptions!$C$25 -> 732.23588 | H31: =(H16+H18)*Assumptions!$C$25 -> 801.66284 | I31: =(I16+I18)*Assumptions!$C$25 -> 820.70159 | J31: =(J16+J18)*Assumptions!$C$25 -> 876.99156 | ... AL31: =(AL16+AL18)*Assumptions!$C$25 -> 1885.941
A32: Marketing | C32: =INDEX(Assumptions!$C$43:$E$43,C6) -> 1500 | D32: =INDEX(Assumptions!$C$43:$E$43,D6) -> 1500 | E32: =INDEX(Assumptions!$C$43:$E$43,E6) -> 1500 | F32: =INDEX(Assumptions!$C$43:$E$43,F6) -> 1500 | G32: =INDEX(Assumptions!$C$43:$E$43,G6) -> 1500 | H32: =INDEX(Assumptions!$C$43:$E$43,H6) -> 1500 | I32: =INDEX(Assumptions!$C$43:$E$43,I6) -> 1500 | J32: =INDEX(Assumptions!$C$43:$E$43,J6) -> 1500 | ... AL32: =INDEX(Assumptions!$C$43:$E$43,AL6) -> 1000
A33: Legal and accounting | C33: =INDEX(Assumptions!$C$44:$E$44,C6) -> 1000 | D33: =INDEX(Assumptions!$C$44:$E$44,D6) -> 1000 | E33: =INDEX(Assumptions!$C$44:$E$44,E6) -> 1000 | F33: =INDEX(Assumptions!$C$44:$E$44,F6) -> 1000 | G33: =INDEX(Assumptions!$C$44:$E$44,G6) -> 1000 | H33: =INDEX(Assumptions!$C$44:$E$44,H6) -> 1000 | I33: =INDEX(Assumptions!$C$44:$E$44,I6) -> 1000 | J33: =INDEX(Assumptions!$C$44:$E$44,J6) -> 1000 | ... AL33: =INDEX(Assumptions!$C$44:$E$44,AL6) -> 600
A34: Delivery (net of fees) | C34: =IF(C4>=Assumptions!$C$7,C16/Assumptions!$C$27*Assumptions!$C$28*Assumptions!$C$29,0) -> 0 | D34: =IF(D4>=Assumptions!$C$7,D16/Assumptions!$C$27*Assumptions!$C$28*Assumptions!$C$29,0) -> 0 | E34: =IF(E4>=Assumptions!$C$7,E16/Assumptions!$C$27*Assumptions!$C$28*Assumptions!$C$29,0) -> 0 | F34: =IF(F4>=Assumptions!$C$7,F16/Assumptions!$C$27*Assumptions!$C$28*Assumptions!$C$29,0) -> 0 | G34: =IF(G4>=Assumptions!$C$7,G16/Assumptions!$C$27*Assumptions!$C$28*Assumptions!$C$29,0) -> 0 | H34: =IF(H4>=Assumptions!$C$7,H16/Assumptions!$C$27*Assumptions!$C$28*Assumptions!$C$29,0) -> 0 | I34: =IF(I4>=Assumptions!$C$7,I16/Assumptions!$C$27*Assumptions!$C$28*Assumptions!$C$29,0) -> 328.45387 | J34: =IF(J4>=Assumptions!$C$7,J16/Assumptions!$C$27*Assumptions!$C$28*Assumptions!$C$29,0) -> 354.83979 | ... AL34: =IF(AL4>=Assumptions!$C$7,AL16/Assumptions!$C$27*Assumptions!$C$28*Assumptions!$C$29,0) -> 790.374
A35: Supplies and packaging | C35: =C16*Assumptions!$C$26 -> 133.0875 | D35: =D16*Assumptions!$C$26 -> 167.94375 | E35: =E16*Assumptions!$C$26 -> 202.20427 | F35: =F16*Assumptions!$C$26 -> 235.88099 | G35: =G16*Assumptions!$C$26 -> 268.98557 | H35: =H16*Assumptions!$C$26 -> 301.52946 | I35: =I16*Assumptions!$C$26 -> 328.45387 | J35: =J16*Assumptions!$C$26 -> 354.83979 | ... AL35: =AL16*Assumptions!$C$26 -> 790.374
A36: Other operating | C36: =Assumptions!$C$45 -> 300 | D36: =Assumptions!$C$45 -> 300 | E36: =Assumptions!$C$45 -> 300 | F36: =Assumptions!$C$45 -> 300 | G36: =Assumptions!$C$45 -> 300 | H36: =Assumptions!$C$45 -> 300 | I36: =Assumptions!$C$45 -> 300 | J36: =Assumptions!$C$45 -> 300 | ... AL36: =Assumptions!$C$45 -> 300
A37: Total operating expenses | C37: =SUM(C25:C36) -> 16471.174 | D37: =SUM(D25:D36) -> 16099.04 | E37: =SUM(E25:E36) -> 16214.499 | F37: =SUM(F25:F36) -> 16327.99 | G37: =SUM(G25:G36) -> 16439.553 | H37: =SUM(H25:H36) -> 16549.227 | I37: =SUM(I25:I36) -> 16930.017 | J37: =SUM(J25:J36) -> 17045.324 | ... AL37: =SUM(AL25:AL36) -> 20258.749
A38: EBITDA | C38: =C22-C37 -> 6458.3208 | D38: =D22-D37 -> -7767.7729 | E38: =E22-E37 -> -7193.453 | F38: =F22-F37 -> -6628.9197 | G38: =G22-G37 -> -6073.9772 | H38: =H22-H37 -> -5528.4338 | I38: =I22-I37 -> -6567.1453 | J38: =J22-J37 -> -6151.2157 | ... AL38: =AL22-AL37 -> 1898.1716
A39: Below EBITDA
A40: Depreciation | C40: ='Startup Costs'!$C$22/(Assumptions!$C$47*12) -> 559.52381 | D40: ='Startup Costs'!$C$22/(Assumptions!$C$47*12) -> 559.52381 | E40: ='Startup Costs'!$C$22/(Assumptions!$C$47*12) -> 559.52381 | F40: ='Startup Costs'!$C$22/(Assumptions!$C$47*12) -> 559.52381 | G40: ='Startup Costs'!$C$22/(Assumptions!$C$47*12) -> 559.52381 | H40: ='Startup Costs'!$C$22/(Assumptions!$C$47*12) -> 559.52381 | I40: ='Startup Costs'!$C$22/(Assumptions!$C$47*12) -> 559.52381 | J40: ='Startup Costs'!$C$22/(Assumptions!$C$47*12) -> 559.52381 | ... AL40: ='Startup Costs'!$C$22/(Assumptions!$C$47*12) -> 559.52381
A41: Loan balance (start of month) | C41: =Assumptions!$C$48 -> 100000 | D41: =C41-C43 -> 99539.167 | E41: =D41-D43 -> 99074.109 | F41: =E41-E43 -> 98604.788 | G41: =F41-F43 -> 98131.165 | H41: =G41-G43 -> 97653.201 | I41: =H41-H43 -> 97170.855 | J41: =I41-I43 -> 96684.088 | K41: =J41-J43 -> 96192.858 | ... AL41: =AK41-AK43 -> 81084.234
...

Sheet Annual Summary
A1: Annual summary ($)
B3: Year 1 | C3: Year 2 | D3: Year 3
A4: Active members (end of year) | B4: =INDEX('Monthly P&L'!$C$12:$AL$12,12) -> 718.28133 | C4: =INDEX('Monthly P&L'!$C$12:$AL$12,24) -> 961.92143 | D4: =INDEX('Monthly P&L'!$C$12:$AL$12,36) -> 1045.4683
A5: Beer sales | B5: =SUMIF('Monthly P&L'!$C$6:$AL$6,1,'Monthly P&L'!$C$16:$AL$16) -> 244383.09 | C5: =SUMIF('Monthly P&L'!$C$6:$AL$6,2,'Monthly P&L'!$C$16:$AL$16) -> 488453.82 | D5: =SUMIF('Monthly P&L'!$C$6:$AL$6,3,'Monthly P&L'!$C$16:$AL$16) -> 610152.76
A6: Refunds | B6: =SUMIF('Monthly P&L'!$C$6:$AL$6,1,'Monthly P&L'!$C$17:$AL$17) -> -4398.8955 | C6: =SUMIF('Monthly P&L'!$C$6:$AL$6,2,'Monthly P&L'!$C$17:$AL$17) -> -8792.1688 | D6: =SUMIF('Monthly P&L'!$C$6:$AL$6,3,'Monthly P&L'!$C$17:$AL$17) -> -10982.75
A7: Membership fees | B7: =SUMIF('Monthly P&L'!$C$6:$AL$6,1,'Monthly P&L'!$C$18:$AL$18) -> 67500 | C7: =SUMIF('Monthly P&L'!$C$6:$AL$6,2,'Monthly P&L'!$C$18:$AL$18) -> 87697.628 | D7: =SUMIF('Monthly P&L'!$C$6:$AL$6,3,'Monthly P&L'!$C$18:$AL$18) -> 94547.044
A8: Total revenue | B8: =SUMIF('Monthly P&L'!$C$6:$AL$6,1,'Monthly P&L'!$C$19:$AL$19) -> 307484.19 | C8: =SUMIF('Monthly P&L'!$C$6:$AL$6,2,'Monthly P&L'!$C$19:$AL$19) -> 567359.28 | D8: =SUMIF('Monthly P&L'!$C$6:$AL$6,3,'Monthly P&L'!$C$19:$AL$19) -> 693717.05
A9: Beer COGS | B9: =SUMIF('Monthly P&L'!$C$6:$AL$6,1,'Monthly P&L'!$C$21:$AL$21) -> 166180.5 | C9: =SUMIF('Monthly P&L'!$C$6:$AL$6,2,'Monthly P&L'!$C$21:$AL$21) -> 332148.6 | D9: =SUMIF('Monthly P&L'!$C$6:$AL$6,3,'Monthly P&L'!$C$21:$AL$21) -> 414903.88
A10: Gross profit | B10: =SUMIF('Monthly P&L'!$C$6:$AL$6,1,'Monthly P&L'!$C$22:$AL$22) -> 141303.69 | C10: =SUMIF('Monthly P&L'!$C$6:$AL$6,2,'Monthly P&L'!$C$22:$AL$22) -> 235210.68 | D10: =SUMIF('Monthly P&L'!$C$6:$AL$6,3,'Monthly P&L'!$C$22:$AL$22) -> 278813.18
A11: Gross margin | B11: =IF(B8=0,0,B10/B8) -> 0.45954783 | C11: =IF(C8=0,0,C10/C8) -> 0.41457096 | D11: =IF(D8=0,0,D10/D8) -> 0.40191196
A12: Operating expenses | B12: =SUMIF('Monthly P&L'!$C$6:$AL$6,1,'Monthly P&L'!$C$37:$AL$37) -> 201365.75 | C12: =SUMIF('Monthly P&L'!$C$6:$AL$6,2,'Monthly P&L'!$C$37:$AL$37) -> 235317.71 | D12: =SUMIF('Monthly P&L'!$C$6:$AL$6,3,'Monthly P&L'!$C$37:$AL$37) -> 242293.79
A13: EBITDA | B13: =SUMIF('Monthly P&L'!$C$6:$AL$6,1,'Monthly P&L'!$C$38:$AL$38) -> -60062.06 | C13: =SUMIF('Monthly P&L'!$C$6:$AL$6,2,'Monthly P&L'!$C$38:$AL$38) -> -107.0242 | D13: =SUMIF('Monthly P&L'!$C$6:$AL$6,3,'Monthly P&L'!$C$38:$AL$38) -> 36519.39
A14: Depreciation | B14: =SUMIF('Monthly P&L'!$C$6:$AL$6,1,'Monthly P&L'!$C$40:$AL$40) -> 6714.2857 | C14: =SUMIF('Monthly P&L'!$C$6:$AL$6,2,'Monthly P&L'!$C$40:$AL$40) -> 6714.2857 | D14: =SUMIF('Monthly P&L'!$C$6:$AL$6,3,'Monthly P&L'!$C$40:$AL$40) -> 6714.2857
A15: Interest | B15: =SUMIF('Monthly P&L'!$C$6:$AL$6,1,'Monthly P&L'!$C$42:$AL$42) -> 10712.498 | C15: =SUMIF('Monthly P&L'!$C$6:$AL$6,2,'Monthly P&L'!$C$42:$AL$42) -> 10039.304 | D15: =SUMIF('Monthly P&L'!$C$6:$AL$6,3,'Monthly P&L'!$C$42:$AL$42) -> 9288.2078
A16: Net income (pre-tax) | B16: =SUMIF('Monthly P&L'!$C$6:$AL$6,1,'Monthly P&L'!$C$44:$AL$44) -> -77488.844 | C16: =SUMIF('Monthly P&L'!$C$6:$AL$6,2,'Monthly P&L'!$C$44:$AL$44) -> -16860.614 | D16: =SUMIF('Monthly P&L'!$C$6:$AL$6,3,'Monthly P&L'!$C$44:$AL$44) -> 20516.897
A17: Principal repaid | B17: =SUMIF('Monthly P&L'!$C$6:$AL$6,1,'Monthly P&L'!$C$43:$AL$43) -> 5817.5029 | C17: =SUMIF('Monthly P&L'!$C$6:$AL$6,2,'Monthly P&L'!$C$43:$AL$43) -> 6490.6976 | D17: =SUMIF('Monthly P&L'!$C$6:$AL$6,3,'Monthly P&L'!$C$43:$AL$43) -> 7241.7936
A18: Cash balance (end of year) | B18: =INDEX('Monthly P&L'!$C$47:$AL$47,12) -> 47386.359 | C18: =INDEX('Monthly P&L'!$C$47:$AL$47,24) -> 30749.333 | D18: =INDEX('Monthly P&L'!$C$47:$AL$47,36) -> 50738.722

Sheet Break-even
A1: Break-even (year-1 run rate)
A3: Monthly fixed costs (month 12) | B3: ='Monthly P&L'!$N$25+'Monthly P&L'!$N$26+'Monthly P&L'!$N$27+'Monthly P&L'!$N$28+'Monthly P&L'!$N$29+'Monthly P&L'!$N$32+'Monthly P&L'!$N$33+'Monthly P&L'!$N$36+Assumptions!$C$42 -> 15374.667
A4: Beer contribution per active member per month | B4: =INDEX(Assumptions!$C$19:$E$19,1)*INDEX(Assumptions!$C$20:$E$20,1)*(1-Assumptions!$C$21-Assumptions!$C$25-Assumptions!$C$26-Assumptions!$C$22*Assumptions!$C$23)-Assumptions!$C$30 -> 10.62375
A5: Membership contribution per member per month (Member tier) | B5: =Assumptions!$C$10/12*(1-Assumptions!$C$25) -> 6.05
A6: Total contribution per member per month | B6: =B4+B5 -> 16.67375
A7: Active members needed to cover fixed costs | B7: =IF(B6<=0,0,B3/B6) -> 922.08811
A8: EBITDA stays positive from operating month | B8: =IFERROR(MATCH(1,'Monthly P&L'!$C$49:$AL$49,0),"Not within 36 months") -> 25
A9: Lowest cash balance in 36 months | B9: =MIN('Monthly P&L'!$C$47:$AL$47) -> 30749.333
A11: Contribution uses year-1 participation and spend, and prices every member at the Member fee (conservative).
A13: Sensitivity: active members needed to break even
A14: Rows = beer spend per buying member ($/month). Columns = beer gross margin. Blue headers are editable.
A15: Spend / margin | B15: 0.25 | C15: 0.28 | D15: 0.32 | E15: 0.36 | F15: 0.4
A16: 45 | B16: =IF((INDEX(Assumptions!$C$19:$E$19,1)*$A16*(B$15-Assumptions!$C$25-Assumptions!$C$26-Assumptions!$C$22*Assumptions!$C$23)-Assumptions!$C$30+Assumptions!$C$10/12*(1-Assumptions!$C$25))<=0,"n/a",$B$3/(INDEX(Assumptions!$C$19:$E$19,1)*$A16*(B$15-Assumptions!$C$25-Assumptions!$C$26-Assumptions!$C$22*Assumptions!$C$23)-Assumptions!$C$30+Assumptions!$C$10/12*(1-Assumptions!$C$25))) -> 1359.2367 | C16: =IF((INDEX(Assumptions!$C$19:$E$19,1)*$A16*(C$15-Assumptions!$C$25-Assumptions!$C$26-Assumptions!$C$22*Assumptions!$C$23)-Assumptions!$C$30+Assumptions!$C$10/12*(1-Assumptions!$C$25))<=0,"n/a",$B$3/(INDEX(Assumptions!$C$19:$E$19,1)*$A16*(C$15-Assumptions!$C$25-Assumptions!$C$26-Assumptions!$C$22*Assumptions!$C$23)-Assumptions!$C$30+Assumptions!$C$10/12*(1-Assumptions!$C$25))) -> 1261.3817 | D16: =IF((INDEX(Assumptions!$C$19:$E$19,1)*$A16*(D$15-Assumptions!$C$25-Assumptions!$C$26-Assumptions!$C$22*Assumptions!$C$23)-Assumptions!$C$30+Assumptions!$C$10/12*(1-Assumptions!$C$25))<=0,"n/a",$B$3/(INDEX(Assumptions!$C$19:$E$19,1)*$A16*(D$15-Assumptions!$C$25-Assumptions!$C$26-Assumptions!$C$22*Assumptions!$C$23)-Assumptions!$C$30+Assumptions!$C$10/12*(1-Assumptions!$C$25))) -> 1150.9061 | E16: =IF((INDEX(Assumptions!$C$19:$E$19,1)*$A16*(E$15-Assumptions!$C$25-Assumptions!$C$26-Assumptions!$C$22*Assumptions!$C$23)-Assumptions!$C$30+Assumptions!$C$10/12*(1-Assumptions!$C$25))<=0,"n/a",$B$3/(INDEX(Assumptions!$C$19:$E$19,1)*$A16*(E$15-Assumptions!$C$25-Assumptions!$C$26-Assumptions!$C$22*Assumptions!$C$23)-Assumptions!$C$30+Assumptions!$C$10/12*(1-Assumptions!$C$25))) -> 1058.2236 | F16: =IF((INDEX(Assumptions!$C$19:$E$19,1)*$A16*(F$15-Assumptions!$C$25-Assumptions!$C$26-Assumptions!$C$22*Assumptions!$C$23)-Assumptions!$C$30+Assumptions!$C$10/12*(1-Assumptions!$C$25))<=0,"n/a",$B$3/(INDEX(Assumptions!$C$19:$E$19,1)*$A16*(F$15-Assumptions!$C$25-Assumptions!$C$26-Assumptions!$C$22*Assumptions!$C$23)-Assumptions!$C$30+Assumptions!$C$10/12*(1-Assumptions!$C$25))) -> 979.35611
A17: 55 | B17: =IF((INDEX(Assumptions!$C$19:$E$19,1)*$A17*(B$15-Assumptions!$C$25-Assumptions!$C$26-Assumptions!$C$22*Assumptions!$C$23)-Assumptions!$C$30+Assumptions!$C$10/12*(1-Assumptions!$C$25))<=0,"n/a",$B$3/(INDEX(Assumptions!$C$19:$E$19,1)*$A17*(B$15-Assumptions!$C$25-Assumptions!$C$26-Assumptions!$C$22*Assumptions!$C$23)-Assumptions!$C$30+Assumptions!$C$10/12*(1-Assumptions!$C$25))) -> 1228.6218 | C17: =IF((INDEX(Assumptions!$C$19:$E$19,1)*$A17*(C$15-Assumptions!$C$25-Assumptions!$C$26-Assumptions!$C$22*Assumptions!$C$23)-Assumptions!$C$30+Assumptions!$C$10/12*(1-Assumptions!$C$25))<=0,"n/a",$B$3/(INDEX(Assumptions!$C$19:$E$19,1)*$A17*(C$15-Assumptions!$C$25-Assumptions!$C$26-Assumptions!$C$22*Assumptions!$C$23)-Assumptions!$C$30+Assumptions!$C$10/12*(1-Assumptions!$C$25))) -> 1131.6343 | D17: =IF((INDEX(Assumptions!$C$19:$E$19,1)*$A17*(D$15-Assumptions!$C$25-Assumptions!$C$26-Assumptions!$C$22*Assumptions!$C$23)-Assumptions!$C$30+Assumptions!$C$10/12*(1-Assumptions!$C$25))<=0,"n/a",$B$3/(INDEX(Assumptions!$C$19:$E$19,1)*$A17*(D$15-Assumptions!$C$25-Assumptions!$C$26-Assumptions!$C$22*Assumptions!$C$23)-Assumptions!$C$30+Assumptions!$C$10/12*(1-Assumptions!$C$25))) -> 1023.8686 | E17: =IF((INDEX(Assumptions!$C$19:$E$19,1)*$A17*(E$15-Assumptions!$C$25-Assumptions!$C$26-Assumptions!$C$22*Assumptions!$C$23)-Assumptions!$C$30+Assumptions!$C$10/12*(1-Assumptions!$C$25))<=0,"n/a",$B$3/(INDEX(Assumptions!$C$19:$E$19,1)*$A17*(E$15-Assumptions!$C$25-Assumptions!$C$26-Assumptions!$C$22*Assumptions!$C$23)-Assumptions!$C$30+Assumptions!$C$10/12*(1-Assumptions!$C$25))) -> 934.8433 | F17: =IF((INDEX(Assumptions!$C$19:$E$19,1)*$A17*(F$15-Assumptions!$C$25-Assumptions!$C$26-Assumptions!$C$22*Assumptions!$C$23)-Assumptions!$C$30+Assumptions!$C$10/12*(1-Assumptions!$C$25))<=0,"n/a",$B$3/(INDEX(Assumptions!$C$19:$E$19,1)*$A17*(F$15-Assumptions!$C$25-Assumptions!$C$26-Assumptions!$C$22*Assumptions!$C$23)-Assumptions!$C$30+Assumptions!$C$10/12*(1-Assumptions!$C$25))) -> 860.06107
A18: 65 | B18: =IF((INDEX(Assumptions!$C$19:$E$19,1)*$A18*(B$15-Assumptions!$C$25-Assumptions!$C$26-Assumptions!$C$22*Assumptions!$C$23)-Assumptions!$C$30+Assumptions!$C$10/12*(1-Assumptions!$C$25))<=0,"n/a",$B$3/(INDEX(Assumptions!$C$19:$E$19,1)*$A18*(B$15-Assumptions!$C$25-Assumptions!$C$26-Assumptions!$C$22*Assumptions!$C$23)-Assumptions!$C$30+Assumptions!$C$10/12*(1-Assumptions!$C$25))) -> 1120.9089 | C18: =IF((INDEX(Assumptions!$C$19:$E$19,1)*$A18*(C$15-Assumptions!$C$25-Assumptions!$C$26-Assumptions!$C$22*Assumptions!$C$23)-Assumptions!$C$30+Assumptions!$C$10/12*(1-Assumptions!$C$25))<=0,"n/a",$B$3/(INDEX(Assumptions!$C$19:$E$19,1)*$A18*(C$15-Assumptions!$C$25-Assumptions!$C$26-Assumptions!$C$22*Assumptions!$C$23)-Assumptions!$C$30+Assumptions!$C$10/12*(1-Assumptions!$C$25))) -> 1026.0894 | D18: =IF((INDEX(Assumptions!$C$19:$E$19,1)*$A18*(D$15-Assumptions!$C$25-Assumptions!$C$26-Assumptions!$C$22*Assumptions!$C$23)-Assumptions!$C$30+Assumptions!$C$10/12*(1-Assumptions!$C$25))<=0,"n/a",$B$3/(INDEX(Assumptions!$C$19:$E$19,1)*$A18*(D$15-Assumptions!$C$25-Assumptions!$C$26-Assumptions!$C$22*Assumptions!$C$23)-Assumptions!$C$30+Assumptions!$C$10/12*(1-Assumptions!$C$25))) -> 922.08811 | E18: =IF((INDEX(Assumptions!$C$19:$E$19,1)*$A18*(E$15-Assumptions!$C$25-Assumptions!$C$26-Assumptions!$C$22*Assumptions!$C$23)-Assumptions!$C$30+Assumptions!$C$10/12*(1-Assumptions!$C$25))<=0,"n/a",$B$3/(INDEX(Assumptions!$C$19:$E$19,1)*$A18*(E$15-Assumptions!$C$25-Assumptions!$C$26-Assumptions!$C$22*Assumptions!$C$23)-Assumptions!$C$30+Assumptions!$C$10/12*(1-Assumptions!$C$25))) -> 837.22914 | F18: =IF((INDEX(Assumptions!$C$19:$E$19,1)*$A18*(F$15-Assumptions!$C$25-Assumptions!$C$26-Assumptions!$C$22*Assumptions!$C$23)-Assumptions!$C$30+Assumptions!$C$10/12*(1-Assumptions!$C$25))<=0,"n/a",$B$3/(INDEX(Assumptions!$C$19:$E$19,1)*$A18*(F$15-Assumptions!$C$25-Assumptions!$C$26-Assumptions!$C$22*Assumptions!$C$23)-Assumptions!$C$30+Assumptions!$C$10/12*(1-Assumptions!$C$25))) -> 766.6729
A19: 75 | B19: =IF((INDEX(Assumptions!$C$19:$E$19,1)*$A19*(B$15-Assumptions!$C$25-Assumptions!$C$26-Assumptions!$C$22*Assumptions!$C$23)-Assumptions!$C$30+Assumptions!$C$10/12*(1-Assumptions!$C$25))<=0,"n/a",$B$3/(INDEX(Assumptions!$C$19:$E$19,1)*$A19*(B$15-Assumptions!$C$25-Assumptions!$C$26-Assumptions!$C$22*Assumptions!$C$23)-Assumptions!$C$30+Assumptions!$C$10/12*(1-Assumptions!$C$25))) -> 1030.56 | C19: =IF((INDEX(Assumptions!$C$19:$E$19,1)*$A19*(C$15-Assumptions!$C$25-Assumptions!$C$26-Assumptions!$C$22*Assumptions!$C$23)-Assumptions!$C$30+Assumptions!$C$10/12*(1-Assumptions!$C$25))<=0,"n/a",$B$3/(INDEX(Assumptions!$C$19:$E$19,1)*$A19*(C$15-Assumptions!$C$25-Assumptions!$C$26-Assumptions!$C$22*Assumptions!$C$23)-Assumptions!$C$30+Assumptions!$C$10/12*(1-Assumptions!$C$25))) -> 938.55272 | D19: =IF((INDEX(Assumptions!$C$19:$E$19,1)*$A19*(D$15-Assumptions!$C$25-Assumptions!$C$26-Assumptions!$C$22*Assumptions!$C$23)-Assumptions!$C$30+Assumptions!$C$10/12*(1-Assumptions!$C$25))<=0,"n/a",$B$3/(INDEX(Assumptions!$C$19:$E$19,1)*$A19*(D$15-Assumptions!$C$25-Assumptions!$C$26-Assumptions!$C$22*Assumptions!$C$23)-Assumptions!$C$30+Assumptions!$C$10/12*(1-Assumptions!$C$25))) -> 838.71349 | E19: =IF((INDEX(Assumptions!$C$19:$E$19,1)*$A19*(E$15-Assumptions!$C$25-Assumptions!$C$26-Assumptions!$C$22*Assumptions!$C$23)-Assumptions!$C$30+Assumptions!$C$10/12*(1-Assumptions!$C$25))<=0,"n/a",$B$3/(INDEX(Assumptions!$C$19:$E$19,1)*$A19*(E$15-Assumptions!$C$25-Assumptions!$C$26-Assumptions!$C$22*Assumptions!$C$23)-Assumptions!$C$30+Assumptions!$C$10/12*(1-Assumptions!$C$25))) -> 758.07293 | F19: =IF((INDEX(Assumptions!$C$19:$E$19,1)*$A19*(F$15-Assumptions!$C$25-Assumptions!$C$26-Assumptions!$C$22*Assumptions!$C$23)-Assumptions!$C$30+Assumptions!$C$10/12*(1-Assumptions!$C$25))<=0,"n/a",$B$3/(INDEX(Assumptions!$C$19:$E$19,1)*$A19*(F$15-Assumptions!$C$25-Assumptions!$C$26-Assumptions!$C$22*Assumptions!$C$23)-Assumptions!$C$30+Assumptions!$C$10/12*(1-Assumptions!$C$25))) -> 691.57905
A20: 85 | B20: =IF((INDEX(Assumptions!$C$19:$E$19,1)*$A20*(B$15-Assumptions!$C$25-Assumptions!$C$26-Assumptions!$C$22*Assumptions!$C$23)-Assumptions!$C$30+Assumptions!$C$10/12*(1-Assumptions!$C$25))<=0,"n/a",$B$3/(INDEX(Assumptions!$C$19:$E$19,1)*$A20*(B$15-Assumptions!$C$25-Assumptions!$C$26-Assumptions!$C$22*Assumptions!$C$23)-Assumptions!$C$30+Assumptions!$C$10/12*(1-Assumptions!$C$25))) -> 953.68949 | C20: =IF((INDEX(Assumptions!$C$19:$E$19,1)*$A20*(C$15-Assumptions!$C$25-Assumptions!$C$26-Assumptions!$C$22*Assumptions!$C$23)-Assumptions!$C$30+Assumptions!$C$10/12*(1-Assumptions!$C$25))<=0,"n/a",$B$3/(INDEX(Assumptions!$C$19:$E$19,1)*$A20*(C$15-Assumptions!$C$25-Assumptions!$C$26-Assumptions!$C$22*Assumptions!$C$23)-Assumptions!$C$30+Assumptions!$C$10/12*(1-Assumptions!$C$25))) -> 864.77771 | D20: =IF((INDEX(Assumptions!$C$19:$E$19,1)*$A20*(D$15-Assumptions!$C$25-Assumptions!$C$26-Assumptions!$C$22*Assumptions!$C$23)-Assumptions!$C$30+Assumptions!$C$10/12*(1-Assumptions!$C$25))<=0,"n/a",$B$3/(INDEX(Assumptions!$C$19:$E$19,1)*$A20*(D$15-Assumptions!$C$25-Assumptions!$C$26-Assumptions!$C$22*Assumptions!$C$23)-Assumptions!$C$30+Assumptions!$C$10/12*(1-Assumptions!$C$25))) -> 769.16599 | E20: =IF((INDEX(Assumptions!$C$19:$E$19,1)*$A20*(E$15-Assumptions!$C$25-Assumptions!$C$26-Assumptions!$C$22*Assumptions!$C$23)-Assumptions!$C$30+Assumptions!$C$10/12*(1-Assumptions!$C$25))<=0,"n/a",$B$3/(INDEX(Assumptions!$C$19:$E$19,1)*$A20*(E$15-Assumptions!$C$25-Assumptions!$C$26-Assumptions!$C$22*Assumptions!$C$23)-Assumptions!$C$30+Assumptions!$C$10/12*(1-Assumptions!$C$25))) -> 692.59155 | F20: =IF((INDEX(Assumptions!$C$19:$E$19,1)*$A20*(F$15-Assumptions!$C$25-Assumptions!$C$26-Assumptions!$C$22*Assumptions!$C$23)-Assumptions!$C$30+Assumptions!$C$10/12*(1-Assumptions!$C$25))<=0,"n/a",$B$3/(INDEX(Assumptions!$C$19:$E$19,1)*$A20*(F$15-Assumptions!$C$25-Assumptions!$C$26-Assumptions!$C$22*Assumptions!$C$23)-Assumptions!$C$30+Assumptions!$C$10/12*(1-Assumptions!$C$25))) -> 629.88341
A21: 100 | B21: =IF((INDEX(Assumptions!$C$19:$E$19,1)*$A21*(B$15-Assumptions!$C$25-Assumptions!$C$26-Assumptions!$C$22*Assumptions!$C$23)-Assumptions!$C$30+Assumptions!$C$10/12*(1-Assumptions!$C$25))<=0,"n/a",$B$3/(INDEX(Assumptions!$C$19:$E$19,1)*$A21*(B$15-Assumptions!$C$25-Assumptions!$C$26-Assumptions!$C$22*Assumptions!$C$23)-Assumptions!$C$30+Assumptions!$C$10/12*(1-Assumptions!$C$25))) -> 857.72199 | C21: =IF((INDEX(Assumptions!$C$19:$E$19,1)*$A21*(C$15-Assumptions!$C$25-Assumptions!$C$26-Assumptions!$C$22*Assumptions!$C$23)-Assumptions!$C$30+Assumptions!$C$10/12*(1-Assumptions!$C$25))<=0,"n/a",$B$3/(INDEX(Assumptions!$C$19:$E$19,1)*$A21*(C$15-Assumptions!$C$25-Assumptions!$C$26-Assumptions!$C$22*Assumptions!$C$23)-Assumptions!$C$30+Assumptions!$C$10/12*(1-Assumptions!$C$25))) -> 773.56813 | D21: =IF((INDEX(Assumptions!$C$19:$E$19,1)*$A21*(D$15-Assumptions!$C$25-Assumptions!$C$26-Assumptions!$C$22*Assumptions!$C$23)-Assumptions!$C$30+Assumptions!$C$10/12*(1-Assumptions!$C$25))<=0,"n/a",$B$3/(INDEX(Assumptions!$C$19:$E$19,1)*$A21*(D$15-Assumptions!$C$25-Assumptions!$C$26-Assumptions!$C$22*Assumptions!$C$23)-Assumptions!$C$30+Assumptions!$C$10/12*(1-Assumptions!$C$25))) -> 684.07861 | E21: =IF((INDEX(Assumptions!$C$19:$E$19,1)*$A21*(E$15-Assumptions!$C$25-Assumptions!$C$26-Assumptions!$C$22*Assumptions!$C$23)-Assumptions!$C$30+Assumptions!$C$10/12*(1-Assumptions!$C$25))<=0,"n/a",$B$3/(INDEX(Assumptions!$C$19:$E$19,1)*$A21*(E$15-Assumptions!$C$25-Assumptions!$C$26-Assumptions!$C$22*Assumptions!$C$23)-Assumptions!$C$30+Assumptions!$C$10/12*(1-Assumptions!$C$25))) -> 613.14722 | F21: =IF((INDEX(Assumptions!$C$19:$E$19,1)*$A21*(F$15-Assumptions!$C$25-Assumptions!$C$26-Assumptions!$C$22*Assumptions!$C$23)-Assumptions!$C$30+Assumptions!$C$10/12*(1-Assumptions!$C$25))<=0,"n/a",$B$3/(INDEX(Assumptions!$C$19:$E$19,1)*$A21*(F$15-Assumptions!$C$25-Assumptions!$C$26-Assumptions!$C$22*Assumptions!$C$23)-Assumptions!$C$30+Assumptions!$C$10/12*(1-Assumptions!$C$25))) -> 555.54351

Sheet Budget Export
A1: month | B1: line | C1: amount | E1: Paste A:C (with header) into Admin → Finance → Budget import. Amounts in dollars; refunds are negative.
A2: =TEXT('Monthly P&L'!C$5,"yyyy-mm") -> 2027-04 | B2: beer_sales | C2: =ROUND('Monthly P&L'!C16,0) -> 8873
A3: =TEXT('Monthly P&L'!C$5,"yyyy-mm") -> 2027-04 | B3: refunds | C3: =ROUND('Monthly P&L'!C17,0) -> -160
A4: =TEXT('Monthly P&L'!C$5,"yyyy-mm") -> 2027-04 | B4: membership_fees | C4: =ROUND('Monthly P&L'!C18,0) -> 20250
A5: =TEXT('Monthly P&L'!C$5,"yyyy-mm") -> 2027-04 | B5: beer_cogs | C5: =ROUND('Monthly P&L'!C21,0) -> 6033
A6: =TEXT('Monthly P&L'!C$5,"yyyy-mm") -> 2027-04 | B6: rent | C6: =ROUND('Monthly P&L'!C25,0) -> 3600
A7: =TEXT('Monthly P&L'!C$5,"yyyy-mm") -> 2027-04 | B7: utilities | C7: =ROUND('Monthly P&L'!C26,0) -> 900
A8: =TEXT('Monthly P&L'!C$5,"yyyy-mm") -> 2027-04 | B8: payroll | C8: =ROUND('Monthly P&L'!C27,0) -> 7075
A9: =TEXT('Monthly P&L'!C$5,"yyyy-mm") -> 2027-04 | B9: insurance | C9: =ROUND('Monthly P&L'!C28,0) -> 650
A10: =TEXT('Monthly P&L'!C$5,"yyyy-mm") -> 2027-04 | B10: licenses | C10: =ROUND('Monthly P&L'!C29,0) -> 150
A11: =TEXT('Monthly P&L'!C$5,"yyyy-mm") -> 2027-04 | B11: software | C11: =ROUND('Monthly P&L'!C30,0) -> 232
A12: =TEXT('Monthly P&L'!C$5,"yyyy-mm") -> 2027-04 | B12: payment_processing | C12: =ROUND('Monthly P&L'!C31,0) -> 932
A13: =TEXT('Monthly P&L'!C$5,"yyyy-mm") -> 2027-04 | B13: marketing | C13: =ROUND('Monthly P&L'!C32,0) -> 1500
A14: =TEXT('Monthly P&L'!C$5,"yyyy-mm") -> 2027-04 | B14: professional_fees | C14: =ROUND('Monthly P&L'!C33,0) -> 1000
A15: =TEXT('Monthly P&L'!C$5,"yyyy-mm") -> 2027-04 | B15: delivery | C15: =ROUND('Monthly P&L'!C34,0) -> 0
A16: =TEXT('Monthly P&L'!C$5,"yyyy-mm") -> 2027-04 | B16: supplies | C16: =ROUND('Monthly P&L'!C35,0) -> 133
A17: =TEXT('Monthly P&L'!C$5,"yyyy-mm") -> 2027-04 | B17: other_opex | C17: =ROUND('Monthly P&L'!C36,0) -> 300
A18: =TEXT('Monthly P&L'!C$5,"yyyy-mm") -> 2027-04 | B18: depreciation | C18: =ROUND('Monthly P&L'!C40,0) -> 560
A19: =TEXT('Monthly P&L'!C$5,"yyyy-mm") -> 2027-04 | B19: interest | C19: =ROUND('Monthly P&L'!C42,0) -> 917
A20: =TEXT('Monthly P&L'!D$5,"yyyy-mm") -> 2027-05 | B20: beer_sales | C20: =ROUND('Monthly P&L'!D16,0) -> 11196
A21: =TEXT('Monthly P&L'!D$5,"yyyy-mm") -> 2027-05 | B21: refunds | C21: =ROUND('Monthly P&L'!D17,0) -> -202
A22: =TEXT('Monthly P&L'!D$5,"yyyy-mm") -> 2027-05 | B22: membership_fees | C22: =ROUND('Monthly P&L'!D18,0) -> 4950
A23: =TEXT('Monthly P&L'!D$5,"yyyy-mm") -> 2027-05 | B23: beer_cogs | C23: =ROUND('Monthly P&L'!D21,0) -> 7613
A24: =TEXT('Monthly P&L'!D$5,"yyyy-mm") -> 2027-05 | B24: rent | C24: =ROUND('Monthly P&L'!D25,0) -> 3600
A25: =TEXT('Monthly P&L'!D$5,"yyyy-mm") -> 2027-05 | B25: utilities | C25: =ROUND('Monthly P&L'!D26,0) -> 900
A26: =TEXT('Monthly P&L'!D$5,"yyyy-mm") -> 2027-05 | B26: payroll | C26: =ROUND('Monthly P&L'!D27,0) -> 7075
A27: =TEXT('Monthly P&L'!D$5,"yyyy-mm") -> 2027-05 | B27: insurance | C27: =ROUND('Monthly P&L'!D28,0) -> 650
A28: =TEXT('Monthly P&L'!D$5,"yyyy-mm") -> 2027-05 | B28: licenses | C28: =ROUND('Monthly P&L'!D29,0) -> 150
A29: =TEXT('Monthly P&L'!D$5,"yyyy-mm") -> 2027-05 | B29: software | C29: =ROUND('Monthly P&L'!D30,0) -> 240
A30: =TEXT('Monthly P&L'!D$5,"yyyy-mm") -> 2027-05 | B30: payment_processing | C30: =ROUND('Monthly P&L'!D31,0) -> 517
A31: =TEXT('Monthly P&L'!D$5,"yyyy-mm") -> 2027-05 | B31: marketing | C31: =ROUND('Monthly P&L'!D32,0) -> 1500
A32: =TEXT('Monthly P&L'!D$5,"yyyy-mm") -> 2027-05 | B32: professional_fees | C32: =ROUND('Monthly P&L'!D33,0) -> 1000
A33: =TEXT('Monthly P&L'!D$5,"yyyy-mm") -> 2027-05 | B33: delivery | C33: =ROUND('Monthly P&L'!D34,0) -> 0
A34: =TEXT('Monthly P&L'!D$5,"yyyy-mm") -> 2027-05 | B34: supplies | C34: =ROUND('Monthly P&L'!D35,0) -> 168
A35: =TEXT('Monthly P&L'!D$5,"yyyy-mm") -> 2027-05 | B35: other_opex | C35: =ROUND('Monthly P&L'!D36,0) -> 300
A36: =TEXT('Monthly P&L'!D$5,"yyyy-mm") -> 2027-05 | B36: depreciation | C36: =ROUND('Monthly P&L'!D40,0) -> 560
A37: =TEXT('Monthly P&L'!D$5,"yyyy-mm") -> 2027-05 | B37: interest | C37: =ROUND('Monthly P&L'!D42,0) -> 912
A38: =TEXT('Monthly P&L'!E$5,"yyyy-mm") -> 2027-06 | B38: beer_sales | C38: =ROUND('Monthly P&L'!E16,0) -> 13480
A39: =TEXT('Monthly P&L'!E$5,"yyyy-mm") -> 2027-06 | B39: refunds | C39: =ROUND('Monthly P&L'!E17,0) -> -243
A40: =TEXT('Monthly P&L'!E$5,"yyyy-mm") -> 2027-06 | B40: membership_fees | C40: =ROUND('Monthly P&L'!E18,0) -> 4950
...
